<?xml version="1.0" encoding="UTF-8"?>
<!-- Generated by org.testng.reporters.JUnitReportReporter -->
<testsuite hostname="MSI" failures="0" tests="6" name="com.test.DemoTest" time="0.017" errors="2" timestamp="8 Sep 2021 09:18:09 GMT">
  <testcase classname="com.test.DemoTest" name="sum" time="0.000"/>
  <testcase classname="com.test.DemoTest" name="mult" time="0.001"/>
  <testcase classname="com.test.DemoTest" name="sub" time="0.000"/>
  <testcase classname="com.test.DemoTest" name="Ndiv" time="0.015">
    <error message="expected [0] but found [2]" type="java.lang.AssertionError">
      <![CDATA[java.lang.AssertionError: expected [0] but found [2]
	at org.testng.Assert.fail(Assert.java:94)
	at org.testng.Assert.failNotEquals(Assert.java:494)
	at org.testng.Assert.assertEquals(Assert.java:123)
	at org.testng.Assert.assertEquals(Assert.java:370)
	at org.testng.Assert.assertEquals(Assert.java:380)
	at com.test.DemoTest.Ndiv(DemoTest.java:67)
	at java.base/jdk.internal.reflect.NativeMethodAccessorImpl.invoke0(Native Method)
	at java.base/jdk.internal.reflect.NativeMethodAccessorImpl.invoke(NativeMethodAccessorImpl.java:78)
	at java.base/jdk.internal.reflect.DelegatingMethodAccessorImpl.invoke(DelegatingMethodAccessorImpl.java:43)
	at java.base/java.lang.reflect.Method.invoke(Method.java:567)
	at org.testng.internal.MethodInvocationHelper.invokeMethod(MethodInvocationHelper.java:80)
	at org.testng.internal.Invoker.invokeMethod(Invoker.java:714)
	at org.testng.internal.Invoker.invokeTestMethod(Invoker.java:901)
	at org.testng.internal.Invoker.invokeTestMethods(Invoker.java:1231)
	at org.testng.internal.TestMethodWorker.invokeTestMethods(TestMethodWorker.java:127)
	at org.testng.internal.TestMethodWorker.run(TestMethodWorker.java:111)
	at org.testng.TestRunner.privateRun(TestRunner.java:767)
	at org.testng.TestRunner.run(TestRunner.java:617)
	at org.testng.SuiteRunner.runTest(SuiteRunner.java:334)
	at org.testng.SuiteRunner.runSequentially(SuiteRunner.java:329)
	at org.testng.SuiteRunner.privateRun(SuiteRunner.java:291)
	at org.testng.SuiteRunner.run(SuiteRunner.java:240)
	at org.testng.SuiteRunnerWorker.runSuite(SuiteRunnerWorker.java:52)
	at org.testng.SuiteRunnerWorker.run(SuiteRunnerWorker.java:86)
	at org.testng.TestNG.runSuitesSequentially(TestNG.java:1198)
	at org.testng.TestNG.runSuitesLocally(TestNG.java:1123)
	at org.testng.TestNG.run(TestNG.java:1031)
	at org.apache.maven.surefire.testng.TestNGExecutor.run(TestNGExecutor.java:283)
	at org.apache.maven.surefire.testng.TestNGXmlTestSuite.execute(TestNGXmlTestSuite.java:75)
	at org.apache.maven.surefire.testng.TestNGProvider.invoke(TestNGProvider.java:120)
	at org.apache.maven.surefire.booter.ForkedBooter.invokeProviderInSameClassLoader(ForkedBooter.java:384)
	at org.apache.maven.surefire.booter.ForkedBooter.runSuitesInProcess(ForkedBooter.java:345)
	at org.apache.maven.surefire.booter.ForkedBooter.execute(ForkedBooter.java:126)
	at org.apache.maven.surefire.booter.ForkedBooter.main(ForkedBooter.java:418)
]]>
    </error>
  </testcase> <!-- Ndiv -->
  <testcase classname="com.test.DemoTest" name="div" time="0.000"/>
  <testcase classname="com.test.DemoTest" name="Nsum" time="0.001">
    <error message="expected [10] but found [30]" type="java.lang.AssertionError">
      <![CDATA[java.lang.AssertionError: expected [10] but found [30]
	at org.testng.Assert.fail(Assert.java:94)
	at org.testng.Assert.failNotEquals(Assert.java:494)
	at org.testng.Assert.assertEquals(Assert.java:123)
	at org.testng.Assert.assertEquals(Assert.java:370)
	at org.testng.Assert.assertEquals(Assert.java:380)
	at com.test.DemoTest.Nsum(DemoTest.java:57)
	at java.base/jdk.internal.reflect.NativeMethodAccessorImpl.invoke0(Native Method)
	at java.base/jdk.internal.reflect.NativeMethodAccessorImpl.invoke(NativeMethodAccessorImpl.java:78)
	at java.base/jdk.internal.reflect.DelegatingMethodAccessorImpl.invoke(DelegatingMethodAccessorImpl.java:43)
	at java.base/java.lang.reflect.Method.invoke(Method.java:567)
	at org.testng.internal.MethodInvocationHelper.invokeMethod(MethodInvocationHelper.java:80)
	at org.testng.internal.Invoker.invokeMethod(Invoker.java:714)
	at org.testng.internal.Invoker.invokeTestMethod(Invoker.java:901)
	at org.testng.internal.Invoker.invokeTestMethods(Invoker.java:1231)
	at org.testng.internal.TestMethodWorker.invokeTestMethods(TestMethodWorker.java:127)
	at org.testng.internal.TestMethodWorker.run(TestMethodWorker.java:111)
	at org.testng.TestRunner.privateRun(TestRunner.java:767)
	at org.testng.TestRunner.run(TestRunner.java:617)
	at org.testng.SuiteRunner.runTest(SuiteRunner.java:334)
	at org.testng.SuiteRunner.runSequentially(SuiteRunner.java:329)
	at org.testng.SuiteRunner.privateRun(SuiteRunner.java:291)
	at org.testng.SuiteRunner.run(SuiteRunner.java:240)
	at org.testng.SuiteRunnerWorker.runSuite(SuiteRunnerWorker.java:52)
	at org.testng.SuiteRunnerWorker.run(SuiteRunnerWorker.java:86)
	at org.testng.TestNG.runSuitesSequentially(TestNG.java:1198)
	at org.testng.TestNG.runSuitesLocally(TestNG.java:1123)
	at org.testng.TestNG.run(TestNG.java:1031)
	at org.apache.maven.surefire.testng.TestNGExecutor.run(TestNGExecutor.java:283)
	at org.apache.maven.surefire.testng.TestNGXmlTestSuite.execute(TestNGXmlTestSuite.java:75)
	at org.apache.maven.surefire.testng.TestNGProvider.invoke(TestNGProvider.java:120)
	at org.apache.maven.surefire.booter.ForkedBooter.invokeProviderInSameClassLoader(ForkedBooter.java:384)
	at org.apache.maven.surefire.booter.ForkedBooter.runSuitesInProcess(ForkedBooter.java:345)
	at org.apache.maven.surefire.booter.ForkedBooter.execute(ForkedBooter.java:126)
	at org.apache.maven.surefire.booter.ForkedBooter.main(ForkedBooter.java:418)
]]>
    </error>
  </testcase> <!-- Nsum -->
</testsuite> <!-- com.test.DemoTest -->
